<?xml version="1.0"?>

<robot name="lego_arm">
    
    <link name="base_link">
        <visual>
            <origin xyz="-0.017 -0.056 0.0265" rpy="0.0 0.0 0.0"/>                  
            <geometry>
                <box size="-0.104 -0.200 0.053"/>
            </geometry> 
            <material name="white">
                <color rgba="1 1 1 1"/>
            </material>
        </visual>
    </link>

    <joint name="arm_joint_1" type="continuous">
        <parent link="base_link"/>
        <child link="link_1"/>
        <origin xyz="0.0 0.0 0.098"/>
        <axis xyz="0 0 1"/>
    </joint>      
       
    <link name="link_1">
        <visual>
            <origin xyz="-0.043 0 -0.024" rpy="0.0 -1.57075 0.0"/>
            <geometry>
                <cylinder length="0.105" radius="0.012"/>
            </geometry> 
            <material name="white">
                <color rgba="1 1 1 1"/>
            </material>
        </visual>
    </link>

    <joint name="arm_joint_2" type="continuous">
        <parent link="link_1"/>
        <child link="link_2"/>
        <origin xyz="0.0 0.0 0.0" rpy="1.57075 -2.0735 0.0"/>
        <axis xyz="0 0 1"/>
    </joint>    
       
    <link name="link_2">
        <visual>    
        <origin xyz="0.0665 0.0 0.0" rpy="0.0 1.57075 0.0"/>
        <geometry>
            <cylinder length="0.133" radius="0.012"/>
        </geometry>
        <material name="white">
            <color rgba="1 1 1 1"/>
            </material>
        </visual>
    </link>
    
    
    <joint name="arm_joint_3" type="continuous">
        <parent link="link_2"/>
        <child link="link_3"/>
        <origin xyz="0.133 0.0 0.0" rpy="0.0 0.0 -2.65635"/>
        <axis xyz="0 0 1"/>
    </joint>      
       
    <link name="link_3">
        <visual>    
            <origin xyz="0.0585 0.0 0.0" rpy="1.57075 0.0 -1.57075"/>
            <geometry>
                <cylinder length="0.117" radius="0.012"/>
            </geometry>
            <material name="white">
                <color rgba="1 1 1 1"/>
            </material>
        </visual>
    </link>
       
    <joint name="fixed_joint" type="fixed">
        <parent link="link_3"/>
        <child link="ultrasonic_sensor"/>
        <origin xyz="0.117 0.0 0.0" rpy="1.57075 0.0 1.57075"/>
        <axis xyz="0 0 0"/>
    </joint>

    <link name="ultrasonic_sensor">
        <visual>
        <origin xyz="-0.02 0 -0.0303" rpy="-1.57075 0 -1.57075" />
        <geometry>
            <mesh filename="package://nxt_description/meshes/parts/53792.dae" scale=" 0.0004  0.0004  0.0004"/>
        </geometry>
        </visual>
    </link>
       
 </robot>
