<?xml version="1.0"?>

<robot name="EduBot">
    
  <joint name="base_to_left_body" type="fixed"> 
    <parent link="base_link"/>
    <child link="left_link"/>
    <origin xyz="0.0 0.0325 0.028" rpy="0.0 0.0 0.0"/>
    <axis xyz="0.0 0.0 0.0"/>   
  </joint>

  <joint name="base_to_right_body" type="fixed">
    <parent link="base_link"/>
    <child link="right_link"/>
    <origin xyz="0.0 -0.0325 0.028" rpy="0.0 0.0 0.0"/>
    <axis xyz=""/> 
  </joint>
  
  <joint name="base_to_upper_body" type="fixed">
    <parent link="base_link"/>
    <child link="up_link"/>
    <origin xyz="0.025 0.0 0.052" rpy="0.0 0.0 0.0"/>
    <axis xyz="0.0 0.0 0.0"/>  
  </joint>

  <joint name="base_to_brick" type="fixed">
    <parent link="base_link"/>
    <child link="nxt_link"/>
    <origin xyz="-0.06 0.0 0.063" rpy="0.0 0 0.0"/>
    <axis xyz="0.0 0.0 0.0"/>  
  </joint>


  <joint name="base_to_tail" type="fixed">
    <parent link="base_link"/>
    <child link="tail_link"/>
    <origin xyz="-0.1 0.0 0.0605" rpy="0.0 0.0 0.0"/>
    <axis xyz="0.0 0.0 0.0"/>  
  </joint>


  <joint name="tail_to_caster" type="fixed">
    <parent link="tail_link"/>
    <child link="caster_wheel"/>
    <origin xyz="-0.045 0.0 -0.03" rpy="0.0 0.0 0.0"/>
    <axis xyz="0.0 0.0 0.0"/>  
  </joint>
  

  <joint name="motor_joint_left" type="continuous">
    <parent link="left_link"/>
    <child link="left_wheel"/>
    <origin xyz="0.0 0.0275 0.0" rpy="-1.5708 0.0 0.0"/>
    <axis xyz="0.0 0.0 1.0"/>  
  </joint>


  <joint name="motor_joint_right" type="continuous">
    <parent link="right_link"/>
    <child link="right_wheel"/>
    <origin xyz="0.0 -0.0275 0.0" rpy="-1.5708 0.0 0.0"/>
    <axis xyz="0.0 0.0 1.0"/>  
  </joint>

  <joint name="motor_sensor" type="continuous">
    <parent link="up_link"/>
    <child link="ultrasonic_link"/>
    <origin xyz="0.0 0.0 0.0165" rpy="0.0 0.0 0.0"/>
    <axis xyz="0.0 0.0 1.0"/>  
  </joint>
  
  <joint name="ultra_link_to_scan" type="fixed">
    <parent link="ultrasonic_link"/>
    <child link="ultra_sensor"/>
    <origin xyz="0.0475 0.0 0.0175" rpy="0.0 1.5708 0.0"/>
    <axis xyz="0.0 0.0 0.0"/>  
  </joint>  
  

<!-- LINKS -->

  <link name="base_link">
    <visual>
      <origin xyz="-0.0225 0.0 0.028" rpy="0.0 0.0 0.0"/>                  
      <geometry>
        <box size="0.155 0.023 0.023"/>
      </geometry> 
      <material name="white">
        <color rgba="1 1 1 1"/>
      </material>
    </visual>
  </link>
  
   <link name="left_link">
    <visual>
      <origin xyz="-0.046 0.0 0.0" rpy="0.0 0.0 0.0"/>                  
      <geometry>
        <box size="0.115 0.023 0.023"/>
      </geometry> 
      <material name="white">
        <color rgba="1 1 1 1"/>
      </material>
    </visual>
  </link>
  
    <link name="right_link">
    <visual>
      <origin xyz="-0.046 0.0 0.0" rpy="0.0 0.0 0.0"/>                  
      <geometry>
        <box size="0.115 0.023 0.023"/>
      </geometry> 
      <material name="white">
        <color rgba="1 1 1 1"/>
      </material>
    </visual>
  </link> 
      
  <link name="tail_link">
    <visual>
      <origin xyz="-0.0225 0.0 0.0" rpy="0.0 0.0 0.0"/>                  
      <geometry>
        <box size="0.045 0.025 0.0075"/>
      </geometry> 
      <material name="white">
        <color rgba="1 1 1 1"/>
      </material>
    </visual>
  </link>
  
  <link name="caster_wheel">
    <visual>
      <origin xyz="0.0 0.0 0.0" rpy="0.0 0.0 0.0"/>                  
      <geometry>
        <sphere radius="0.02625"/>
      </geometry> 
      <material name="white">
        <color rgba="1 1 1 1"/>
      </material>
    </visual>
  </link>
  
  <link name="nxt_link">
    <visual>
      <origin xyz="-0.0288 0.0 0.0498" rpy="0.0 1.0472 0.0"/>                  
      <geometry>
        <box size="0.115 0.072 0.0475"/>
      </geometry> 
      <material name="white">
        <color rgba="1 1 1 1"/>
      </material>
    </visual>
  </link>
  
  <link name="up_link">
    <visual>
      <origin xyz="0.0 0.0 0.0" rpy="0.0 0.0 0.0"/>                  
      <geometry>
        <box size="0.025 0.055 0.025"/>
      </geometry> 
      <material name="white">
        <color rgba="1 1 1 1"/>
      </material>
    </visual>
  </link> 
  
  <link name="left_wheel">
    <visual>
      <geometry>
        <cylinder length="0.026" radius="0.028"/>
      </geometry>
      <material name="white">
        <color rgba="1 1 1 1"/>
      </material>
    </visual>
  </link>
  
  <link name="right_wheel">
    <visual>
      <geometry>
        <cylinder length="0.026" radius="0.028"/>
      </geometry>
      <material name="white">
        <color rgba="1 1 1 1"/>
      </material>
    </visual>
  </link>
  
  <link name="ultrasonic_link">
    <visual>
      <origin xyz="0.016 0.0 0.0" rpy="0.0 0.0 1.5708" />
        <geometry>
          <mesh filename="package://nxt_description/meshes/parts/53792.dae" scale=" 0.0004  0.0004  0.0004"/>
        </geometry>
    </visual>
  </link>
  
    <link name="ultra_sensor">
    <visual>
      <origin xyz="0.0 0.0 0.0" rpy="0.0 0.0 0.0" />
        <geometry>
          <cylinder length="0.0005" radius="0.005"/>
        </geometry>
        <material name="white">
          <color rgba="0.0 0.0 0.0 0.0"/>
        </material>
    </visual>
  </link>
  
</robot>
